Workbook

Sheet Instrucciones
C2: SISTEMA DE GESTIÓN DE SEGURIDAD, SALUD OCUPACIONAL Y MEDIO AMBIENTE | G2: SSOMA
C3: PAUTA DE EVALUACIÓN PARA AUDITORÍA – SIGO-ECC-003-06 REV. 02 – RF 06 INCENDIO | G3: CODIGO:10031921-SSOMA-LST-XXX
G4: REV: 0 | H4: FECHA: 26-10-2026
B6: OBJETIVO | C6: Evaluar el cumplimiento del estándar SIGO-ECC-003-06 REV. 02 – RF 06 INCENDIO (Codelco) en el área o contrato auditado: controles críticos CCP1–CCP3 y CCM1–CCM2, y otros controles CP1–CP4 y CM1–CM2.
B7: CÓMO USAR | C7: 1) Completar los datos generales en la hoja "Pauta Auditoría". 2) Evaluar cada ítem en la columna RESULTADO (lista desplegable). 3) Registrar la evidencia observada en todo ítem NC y definir acción correctiva, responsable y plazo. 4) La hoja "Resumen" calcula el cumplimiento automáticamente.
B8: CELDAS A COMPLETAR | C8: Solo las celdas en blanco con borde: datos generales, columna RESULTADO, evidencia observada, acción correctiva, responsable y plazo. No modificar las columnas del requisito ni las fórmulas de la hoja Resumen.
B9: ESCALA | C9: C = Cumple (1 punto) · NC = No cumple (0 puntos) · NA = No aplica (no se considera en el cálculo).
B10: DESVIACIONES CRÍTICAS | C10: En los ítems "Desviación crítica", C significa que la desviación NO se observa y NC que SÍ se observa. Una sola desviación crítica observada deja el resultado como NO CONFORME y obliga a detener la actividad y reportar.
B11: ENTREVISTAS | C11: Aplicar las preguntas de verificación del estándar a trabajador/a, supervisor/a y ejecutivo/a. Si alguna respuesta es "NO": detener la actividad, aplicar tarjeta verde y notificar al supervisor (según anexos del estándar).
B12: % CUMPLIMIENTO | C12: Se calcula como C / (C + NC), por control, por componente y en total.
B13: CRITERIO DE RESULTADO | C13: ≥ 90 % Satisfactorio · 75 % – 89 % Aceptable con observaciones · < 75 % Deficiente · cualquier desviación crítica = NO CONFORME. (Umbrales propuestos; ajustar a la política de auditorías de la empresa o del mandante.)
B14: EJEMPLO DE LLENADO | C14: Ítem CCP2-ED2 · Resultado: NC · Evidencia observada: "PTC N° 1234 sin firma del supervisor autorizante" · Acción: "Reinstruir al supervisor y bloquear PTC sin firma" · Responsable: Jefe de terreno · Plazo: 30-10-2026.

Sheet Pauta Auditoría
E2: SISTEMA DE GESTIÓN DE SEGURIDAD, SALUD OCUPACIONAL Y MEDIO AMBIENTE | K2: SSOMA
E3: PAUTA DE EVALUACIÓN PARA AUDITORÍA – SIGO-ECC-003-06 REV. 02 – RF 06 INCENDIO | K3: CODIGO:10031921-SSOMA-LST-XXX
K4: REV: 0 | M4: FECHA: 26-10-2026
B6: OBRA O CONTRATO: | F6: ÁREA / INSTALACIÓN AUDITADA: | I6: DUEÑO/A DEL CONTROL:
B7: AUDITOR/A LÍDER: | F7: EQUIPO AUDITOR: | I7: FECHA AUDITORÍA: | L7: TIPO: INTERNA / EXTERNA
B9: N° ÍTEM | C9: CONTROL | D9: COMPONENTE | E9: REQUISITO / DESVIACIÓN / PREGUNTA | F9: CRITERIO Y EVIDENCIA A VERIFICAR | G9: FRECUENCIA MONITOREO | H9: MÉTODO | I9: RESULTADO (C / NC / NA) | J9: EVIDENCIA OBSERVADA / HALLAZGO | K9: ACCIÓN CORRECTIVA | L9: RESPONSABLE | M9: PLAZO
B10: CCP1 – MAPEO DE ÁREAS CRÍTICAS Y GESTIÓN DE MATERIALES COMBUSTIBLES E INFLAMABLES (Preventivo crítico)
B11: CCP1-ED1 | C11: CCP1 | D11: Estándar de desempeño | E11: Mapa de áreas críticas de riesgo de incendio | F11: Verificar que el proceso para identificar y mapear áreas críticas esté documentado, actualizado y difundido. En terreno verificar que los mapas son visibles y conocidos por el personal. | G11: Semestral | H11: Documental / Terreno
B12: CCP1-ED2 | C12: CCP1 | D12: Estándar de desempeño | E12: Procedimiento de almacenamiento y segregación | F12: Solicitar el procedimiento que define los requisitos para bodegas y zonas de almacenamiento (ventilación, contención, señalización). | G12: Anual | H12: Documental
B13: CCP1-ED3 | C13: CCP1 | D13: Estándar de desempeño | E13: Matriz de incompatibilidad química aplicada | F13: Solicitar la matriz de incompatibilidad y verificar en terreno que los productos químicos están segregados según corresponda. | G13: Mensual | H13: Documental / Terreno
B14: CCP1-ED4 | C14: CCP1 | D14: Estándar de desempeño | E14: Inventario y cantidades máximas controladas | F14: Solicitar el inventario de la bodega y verificar que no se exceden las cantidades máximas de almacenamiento permitidas. | G14: Trimestral | H14: Documental / Terreno
B15: CCP1-ED5 | C15: CCP1 | D15: Estándar de desempeño | E15: Hojas de Datos de Seguridad (HDS) disponibles | F15: Verificar que las HDS de todos los productos almacenados están disponibles, actualizadas y son conocidas por el personal. | G15: Semestral | H15: Documental / Terreno
B16: CCP1-ED6 | C16: CCP1 | D16: Estándar de desempeño | E16: Procedimientos de manipulación y derrame | F16: Solicitar los procedimientos para el trasvasije seguro y para la respuesta a derrames. Verificar que los kits de derrame están completos. | G16: Anual | H16: Documental / Terreno
B17: CCP1-DV1 | C17: CCP1 | D17: Desviación crítica | E17: Se almacenan materiales inflamables (ej. combustibles, solventes) junto a fuentes de ignición evidentes o en áreas no autorizadas. | F17: C = la desviación NO se observa · NC = se observa → detener la actividad y reportar | G17: — | H17: Terreno
B18: CCP1-DV2 | C18: CCP1 | D18: Desviación crítica | E18: Se almacenan productos químicos incompatibles (ej. ácidos con bases, oxidantes con combustibles) en la misma área de contención. | F18: C = la desviación NO se observa · NC = se observa → detener la actividad y reportar | G18: — | H18: Terreno
B19: CCP1-DV3 | C19: CCP1 | D19: Desviación crítica | E19: Se realiza trasvasije de combustible u otro líquido inflamable sin controlar derrames o la electricidad estática. | F19: C = la desviación NO se observa · NC = se observa → detener la actividad y reportar | G19: — | H19: Terreno
B20: CCP1-DV4 | C20: CCP1 | D20: Desviación crítica | E20: Una bodega de inflamables no cuenta con los sistemas básicos de seguridad requeridos (ventilación, contención de derrames). | F20: C = la desviación NO se observa · NC = se observa → detener la actividad y reportar | G20: — | H20: Terreno
B21: CCP1-DV5 | C21: CCP1 | D21: Desviación crítica | E21: Se acumula un derrame significativo de líquido inflamable y no se toman acciones inmediatas para limpiarlo y controlarlo. | F21: C = la desviación NO se observa · NC = se observa → detener la actividad y reportar | G21: — | H21: Terreno
B22: CCP1-EN1 | C22: CCP1 | D22: Entrevista | E22: Trabajador/a: ¿Conozco el mapa de riesgo de incendio del área? | F22: Entrevistar a trabajadores del área. C = responde y demuestra conocimiento. | G22: — | H22: Entrevista
... B24: CCP1-EN3 | C24: CCP1 | D24: Entrevista | E24: Ejecutivo/a: ¿Se cuenta con un mapa de riesgo de incendio y el personal lo conoce? ¿Están segregados y almacenados los materiales combustibles e inflamables? | F24: Entrevistar al ejecutivo/a o dueño/a del control. | G24: — | H24: Entrevista
B25: CCP2 – CONTROL DE TRABAJOS EN CALIENTE (Preventivo crítico)
B26: CCP2-ED1 | C26: CCP2 | D26: Estándar de desempeño | E26: Procedimiento de trabajo en caliente | F26: Solicitar el procedimiento vigente que define los requisitos para la planificación, autorización y ejecución de trabajos en caliente. | G26: Anual | H26: Documental
B27: CCP2-ED2 | C27: CCP2 | D27: Estándar de desempeño | E27: Permiso de Trabajo en Caliente (PTC) | F27: Solicitar el PTC de una tarea en ejecución o recién terminada, verificando su correcto llenado, firmas y autorización. | G27: Diario | H27: Documental
B28: CCP2-ED3 | C28: CCP2 | D28: Estándar de desempeño | E28: Inspección y segregación del área | F28: Verificar en terreno que el área del trabajo en caliente está limpia de combustibles y segregada físicamente (biombos, mantas). | G28: Por evento | H28: Terreno
B29: CCP2-ED4 | C29: CCP2 | D29: Estándar de desempeño | E29: Asignación de vigía de fuego | F29: Verificar en el PTC o en terreno que se ha designado un vigía de fuego exclusivo para la tarea y que permanece el tiempo requerido. | G29: Por evento | H29: Documental / Terreno
B30: CCP2-ED5 | C30: CCP2 | D30: Estándar de desempeño | E30: Equipos de extinción disponibles | F30: Verificar en terreno la existencia de un extintor operativo y apropiado en el punto de trabajo en caliente. | G30: Por evento | H30: Terreno
B31: CCP2-ED6 | C31: CCP2 | D31: Estándar de desempeño | E31: Personal capacitado | F31: Solicitar registros de capacitación: curso del riesgo de fatalidad y curso para ejecutor de trabajo en caliente y vigía. | G31: Anual | H31: Documental
B32: CCP2-DV1 | C32: CCP2 | D32: Desviación crítica | E32: Se ejecuta un trabajo en caliente (soldadura, oxicorte, etc.) sin un permiso de trabajo debidamente autorizado. | F32: C = la desviación NO se observa · NC = se observa → detener la actividad y reportar | G32: — | H32: Terreno
B33: CCP2-DV2 | C33: CCP2 | D33: Desviación crítica | E33: Se realiza un trabajo en caliente en un área con materiales combustibles o inflamables no retirados o protegidos. | F33: C = la desviación NO se observa · NC = se observa → detener la actividad y reportar | G33: — | H33: Terreno
B34: CCP2-DV3 | C34: CCP2 | D34: Desviación crítica | E34: Se realiza soldadura o corte en un estanque o tubería no certificado como purgado y libre de gases inflamables. | F34: C = la desviación NO se observa · NC = se observa → detener la actividad y reportar | G34: — | H34: Terreno
B35: CCP2-DV4 | C35: CCP2 | D35: Desviación crítica | E35: No se cuenta con un extintor operativo en el lugar donde se realiza el trabajo en caliente. | F35: C = la desviación NO se observa · NC = se observa → detener la actividad y reportar | G35: — | H35: Terreno
B36: CCP2-DV5 | C36: CCP2 | D36: Desviación crítica | E36: No se asigna un vigía de fuego durante una tarea de soldadura o corte en un área de alto riesgo de incendio. | F36: C = la desviación NO se observa · NC = se observa → detener la actividad y reportar | G36: — | H36: Terreno
B37: CCP2-EN1 | C37: CCP2 | D37: Entrevista | E37: Trabajador/a: ¿Tengo el permiso para el trabajo en caliente, instalé la segregación (biombos, mantas ignífugas), confirmé que el área está libre de combustibles y cuento con un extintor operativo? | F37: Entrevistar a ejecutores y vigía en terreno. | G37: — | H37: Entrevista
... B39: CCP2-EN3 | C39: CCP2 | D39: Entrevista | E39: Ejecutivo/a: ¿Se garantiza que todo trabajo en caliente cuente con permiso formal, área segregada y vigilancia continua hasta su finalización y posterior a éste? | F39: Entrevistar al ejecutivo/a o dueño/a del control. | G39: — | H39: Entrevista
B40: CCP3 – SISTEMAS DE PROTECCIÓN CONTRA FUENTES DE IGNICIÓN (Preventivo crítico)
B41: CCP3-ED1 | C41: CCP3 | D41: Estándar de desempeño | E41: Protecciones eléctricas certificadas y operativas | F41: Solicitar los registros de pruebas y certificación de las protecciones de sobrecarga y cortocircuito de equipos críticos. | G41: Anual | H41: Documental
B42: CCP3-ED2 | C42: CCP3 | D42: Estándar de desempeño | E42: Programa de inspección termográfica | F42: Solicitar el programa de termografía y los informes de las últimas inspecciones a tableros eléctricos y equipos mecánicos. | G42: Trimestral | H42: Documental
B43: CCP3-ED3 | C43: CCP3 | D43: Estándar de desempeño | E43: Gestión de hallazgos termográficos | F43: Solicitar los planes de acción derivados de los informes de termografía y verificar el cierre de las anomalías detectadas. | G43: Mensual | H43: Documental
B44: CCP3-ED4 | C44: CCP3 | D44: Estándar de desempeño | E44: Integridad de cables e instalaciones eléctricas | F44: Solicitar los registros de inspección planeada que verifiquen el buen estado de cables, canalizaciones y tableros eléctricos. | G44: Mensual | H44: Documental / Terreno
B45: CCP3-ED5 | C45: CCP3 | D45: Estándar de desempeño | E45: Sistemas de detección de temperatura operativos | F45: Verificar en terreno o en sala de control que los sensores de temperatura de equipos críticos (correas, motores) están en línea y funcionando. | G45: Semanal | H45: Terreno
...

Sheet Resumen
D2: SISTEMA DE GESTIÓN DE SEGURIDAD, SALUD OCUPACIONAL Y MEDIO AMBIENTE | I2: SSOMA
D3: RESUMEN DE AUDITORÍA – SIGO-ECC-003-06 REV. 02 – RF 06 INCENDIO | I3: CODIGO:10031921-SSOMA-LST-XXX
I4: REV: 0 | J4: FECHA: 26-10-2026
B6: A. CUMPLIMIENTO POR CONTROL
B7: CÓDIGO | C7: CONTROL | D7: TIPO | E7: N° ÍTEMS | F7: C | G7: NC | H7: NA | I7: % CUMPLIMIENTO | J7: DESVIACIONES CRÍTICAS
B8: CCP1 | C8: Mapeo de áreas críticas y Gestión de Materiales Combustibles e Inflamables | D8: Preventivo crítico | E8: =COUNTIF('Pauta Auditoría'!$C$10:$C$113,B8) -> 14 | F8: =COUNTIFS('Pauta Auditoría'!$C$10:$C$113,B8,'Pauta Auditoría'!$I$10:$I$113,"C") -> 0 | G8: =COUNTIFS('Pauta Auditoría'!$C$10:$C$113,B8,'Pauta Auditoría'!$I$10:$I$113,"NC") -> 0 | H8: =COUNTIFS('Pauta Auditoría'!$C$10:$C$113,B8,'Pauta Auditoría'!$I$10:$I$113,"NA") -> 0 | I8: =IF(F8+G8=0,"",F8/(F8+G8)) | J8: =COUNTIFS('Pauta Auditoría'!$C$10:$C$113,B8,'Pauta Auditoría'!$D$10:$D$113,"Desviación crítica",'Pauta Auditoría'!$I$10:$I$113,"NC") -> 0
B9: CCP2 | C9: Control de trabajos en caliente | D9: Preventivo crítico | E9: =COUNTIF('Pauta Auditoría'!$C$10:$C$113,B9) -> 14 | F9: =COUNTIFS('Pauta Auditoría'!$C$10:$C$113,B9,'Pauta Auditoría'!$I$10:$I$113,"C") -> 0 | G9: =COUNTIFS('Pauta Auditoría'!$C$10:$C$113,B9,'Pauta Auditoría'!$I$10:$I$113,"NC") -> 0 | H9: =COUNTIFS('Pauta Auditoría'!$C$10:$C$113,B9,'Pauta Auditoría'!$I$10:$I$113,"NA") -> 0 | I9: =IF(F9+G9=0,"",F9/(F9+G9)) | J9: =COUNTIFS('Pauta Auditoría'!$C$10:$C$113,B9,'Pauta Auditoría'!$D$10:$D$113,"Desviación crítica",'Pauta Auditoría'!$I$10:$I$113,"NC") -> 0
B10: CCP3 | C10: Sistemas de protección contra fuentes de ignición | D10: Preventivo crítico | E10: =COUNTIF('Pauta Auditoría'!$C$10:$C$113,B10) -> 14 | F10: =COUNTIFS('Pauta Auditoría'!$C$10:$C$113,B10,'Pauta Auditoría'!$I$10:$I$113,"C") -> 0 | G10: =COUNTIFS('Pauta Auditoría'!$C$10:$C$113,B10,'Pauta Auditoría'!$I$10:$I$113,"NC") -> 0 | H10: =COUNTIFS('Pauta Auditoría'!$C$10:$C$113,B10,'Pauta Auditoría'!$I$10:$I$113,"NA") -> 0 | I10: =IF(F10+G10=0,"",F10/(F10+G10)) | J10: =COUNTIFS('Pauta Auditoría'!$C$10:$C$113,B10,'Pauta Auditoría'!$D$10:$D$113,"Desviación crítica",'Pauta Auditoría'!$I$10:$I$113,"NC") -> 0
B11: CCM1 | C11: Sistemas de detección y extinción de incendios | D11: Mitigador crítico | E11: =COUNTIF('Pauta Auditoría'!$C$10:$C$113,B11) -> 14 | F11: =COUNTIFS('Pauta Auditoría'!$C$10:$C$113,B11,'Pauta Auditoría'!$I$10:$I$113,"C") -> 0 | G11: =COUNTIFS('Pauta Auditoría'!$C$10:$C$113,B11,'Pauta Auditoría'!$I$10:$I$113,"NC") -> 0 | H11: =COUNTIFS('Pauta Auditoría'!$C$10:$C$113,B11,'Pauta Auditoría'!$I$10:$I$113,"NA") -> 0 | I11: =IF(F11+G11=0,"",F11/(F11+G11)) | J11: =COUNTIFS('Pauta Auditoría'!$C$10:$C$113,B11,'Pauta Auditoría'!$D$10:$D$113,"Desviación crítica",'Pauta Auditoría'!$I$10:$I$113,"NC") -> 0
B12: CCM2 | C12: Capacidad de respuesta ante emergencias | D12: Mitigador crítico | E12: =COUNTIF('Pauta Auditoría'!$C$10:$C$113,B12) -> 14 | F12: =COUNTIFS('Pauta Auditoría'!$C$10:$C$113,B12,'Pauta Auditoría'!$I$10:$I$113,"C") -> 0 | G12: =COUNTIFS('Pauta Auditoría'!$C$10:$C$113,B12,'Pauta Auditoría'!$I$10:$I$113,"NC") -> 0 | H12: =COUNTIFS('Pauta Auditoría'!$C$10:$C$113,B12,'Pauta Auditoría'!$I$10:$I$113,"NA") -> 0 | I12: =IF(F12+G12=0,"",F12/(F12+G12)) | J12: =COUNTIFS('Pauta Auditoría'!$C$10:$C$113,B12,'Pauta Auditoría'!$D$10:$D$113,"Desviación crítica",'Pauta Auditoría'!$I$10:$I$113,"NC") -> 0
B13: CP1 | C13: Zonas designadas para fumar | D13: Otro control preventivo | E13: =COUNTIF('Pauta Auditoría'!$C$10:$C$113,B13) -> 3 | F13: =COUNTIFS('Pauta Auditoría'!$C$10:$C$113,B13,'Pauta Auditoría'!$I$10:$I$113,"C") -> 0 | G13: =COUNTIFS('Pauta Auditoría'!$C$10:$C$113,B13,'Pauta Auditoría'!$I$10:$I$113,"NC") -> 0 | H13: =COUNTIFS('Pauta Auditoría'!$C$10:$C$113,B13,'Pauta Auditoría'!$I$10:$I$113,"NA") -> 0 | I13: =IF(F13+G13=0,"",F13/(F13+G13)) | J13: =COUNTIFS('Pauta Auditoría'!$C$10:$C$113,B13,'Pauta Auditoría'!$D$10:$D$113,"Desviación crítica",'Pauta Auditoría'!$I$10:$I$113,"NC") -> 0
B14: CP2 | C14: Sistema de refrigeración de equipos | D14: Otro control preventivo | E14: =COUNTIF('Pauta Auditoría'!$C$10:$C$113,B14) -> 4 | F14: =COUNTIFS('Pauta Auditoría'!$C$10:$C$113,B14,'Pauta Auditoría'!$I$10:$I$113,"C") -> 0 | G14: =COUNTIFS('Pauta Auditoría'!$C$10:$C$113,B14,'Pauta Auditoría'!$I$10:$I$113,"NC") -> 0 | H14: =COUNTIFS('Pauta Auditoría'!$C$10:$C$113,B14,'Pauta Auditoría'!$I$10:$I$113,"NA") -> 0 | I14: =IF(F14+G14=0,"",F14/(F14+G14)) | J14: =COUNTIFS('Pauta Auditoría'!$C$10:$C$113,B14,'Pauta Auditoría'!$D$10:$D$113,"Desviación crítica",'Pauta Auditoría'!$I$10:$I$113,"NC") -> 0
B15: CP3 | C15: Enclavamiento de sistemas de aire acondicionado en salas eléctricas | D15: Otro control preventivo | E15: =COUNTIF('Pauta Auditoría'!$C$10:$C$113,B15) -> 4 | F15: =COUNTIFS('Pauta Auditoría'!$C$10:$C$113,B15,'Pauta Auditoría'!$I$10:$I$113,"C") -> 0 | G15: =COUNTIFS('Pauta Auditoría'!$C$10:$C$113,B15,'Pauta Auditoría'!$I$10:$I$113,"NC") -> 0 | H15: =COUNTIFS('Pauta Auditoría'!$C$10:$C$113,B15,'Pauta Auditoría'!$I$10:$I$113,"NA") -> 0 | I15: =IF(F15+G15=0,"",F15/(F15+G15)) | J15: =COUNTIFS('Pauta Auditoría'!$C$10:$C$113,B15,'Pauta Auditoría'!$D$10:$D$113,"Desviación crítica",'Pauta Auditoría'!$I$10:$I$113,"NC") -> 0
B16: CP4 | C16: Protecciones para mangueras hidráulicas | D16: Otro control preventivo | E16: =COUNTIF('Pauta Auditoría'!$C$10:$C$113,B16) -> 4 | F16: =COUNTIFS('Pauta Auditoría'!$C$10:$C$113,B16,'Pauta Auditoría'!$I$10:$I$113,"C") -> 0 | G16: =COUNTIFS('Pauta Auditoría'!$C$10:$C$113,B16,'Pauta Auditoría'!$I$10:$I$113,"NC") -> 0 | H16: =COUNTIFS('Pauta Auditoría'!$C$10:$C$113,B16,'Pauta Auditoría'!$I$10:$I$113,"NA") -> 0 | I16: =IF(F16+G16=0,"",F16/(F16+G16)) | J16: =COUNTIFS('Pauta Auditoría'!$C$10:$C$113,B16,'Pauta Auditoría'!$D$10:$D$113,"Desviación crítica",'Pauta Auditoría'!$I$10:$I$113,"NC") -> 0
B17: CM1 | C17: Zanjas cortafuego | D17: Otro control mitigador | E17: =COUNTIF('Pauta Auditoría'!$C$10:$C$113,B17) -> 4 | F17: =COUNTIFS('Pauta Auditoría'!$C$10:$C$113,B17,'Pauta Auditoría'!$I$10:$I$113,"C") -> 0 | G17: =COUNTIFS('Pauta Auditoría'!$C$10:$C$113,B17,'Pauta Auditoría'!$I$10:$I$113,"NC") -> 0 | H17: =COUNTIFS('Pauta Auditoría'!$C$10:$C$113,B17,'Pauta Auditoría'!$I$10:$I$113,"NA") -> 0 | I17: =IF(F17+G17=0,"",F17/(F17+G17)) | J17: =COUNTIFS('Pauta Auditoría'!$C$10:$C$113,B17,'Pauta Auditoría'!$D$10:$D$113,"Desviación crítica",'Pauta Auditoría'!$I$10:$I$113,"NC") -> 0
B18: CM2 | C18: Vías de evacuación y salidas de emergencia despejadas y señalizadas | D18: Otro control mitigador | E18: =COUNTIF('Pauta Auditoría'!$C$10:$C$113,B18) -> 4 | F18: =COUNTIFS('Pauta Auditoría'!$C$10:$C$113,B18,'Pauta Auditoría'!$I$10:$I$113,"C") -> 0 | G18: =COUNTIFS('Pauta Auditoría'!$C$10:$C$113,B18,'Pauta Auditoría'!$I$10:$I$113,"NC") -> 0 | H18: =COUNTIFS('Pauta Auditoría'!$C$10:$C$113,B18,'Pauta Auditoría'!$I$10:$I$113,"NA") -> 0 | I18: =IF(F18+G18=0,"",F18/(F18+G18)) | J18: =COUNTIFS('Pauta Auditoría'!$C$10:$C$113,B18,'Pauta Auditoría'!$D$10:$D$113,"Desviación crítica",'Pauta Auditoría'!$I$10:$I$113,"NC") -> 0
B19: TOTAL | E19: =SUM(E8:E18) -> 93 | F19: =SUM(F8:F18) -> 0 | G19: =SUM(G8:G18) -> 0 | H19: =SUM(H8:H18) -> 0 | I19: =IF(F19+G19=0,"",F19/(F19+G19)) | J19: =SUM(J8:J18) -> 0
B21: B. CUMPLIMIENTO POR COMPONENTE
C22: COMPONENTE | E22: N° ÍTEMS | F22: C | G22: NC | H22: NA | I22: % CUMPLIMIENTO
C23: Estándar de desempeño | E23: =COUNTIF('Pauta Auditoría'!$D$10:$D$113,C23) -> 30 | F23: =COUNTIFS('Pauta Auditoría'!$D$10:$D$113,C23,'Pauta Auditoría'!$I$10:$I$113,"C") -> 0 | G23: =COUNTIFS('Pauta Auditoría'!$D$10:$D$113,C23,'Pauta Auditoría'!$I$10:$I$113,"NC") -> 0 | H23: =COUNTIFS('Pauta Auditoría'!$D$10:$D$113,C23,'Pauta Auditoría'!$I$10:$I$113,"NA") -> 0 | I23: =IF(F23+G23=0,"",F23/(F23+G23))
C24: Desviación crítica | E24: =COUNTIF('Pauta Auditoría'!$D$10:$D$113,C24) -> 25 | F24: =COUNTIFS('Pauta Auditoría'!$D$10:$D$113,C24,'Pauta Auditoría'!$I$10:$I$113,"C") -> 0 | G24: =COUNTIFS('Pauta Auditoría'!$D$10:$D$113,C24,'Pauta Auditoría'!$I$10:$I$113,"NC") -> 0 | H24: =COUNTIFS('Pauta Auditoría'!$D$10:$D$113,C24,'Pauta Auditoría'!$I$10:$I$113,"NA") -> 0 | I24: =IF(F24+G24=0,"",F24/(F24+G24))
C25: Entrevista | E25: =COUNTIF('Pauta Auditoría'!$D$10:$D$113,C25) -> 15 | F25: =COUNTIFS('Pauta Auditoría'!$D$10:$D$113,C25,'Pauta Auditoría'!$I$10:$I$113,"C") -> 0 | G25: =COUNTIFS('Pauta Auditoría'!$D$10:$D$113,C25,'Pauta Auditoría'!$I$10:$I$113,"NC") -> 0 | H25: =COUNTIFS('Pauta Auditoría'!$D$10:$D$113,C25,'Pauta Auditoría'!$I$10:$I$113,"NA") -> 0 | I25: =IF(F25+G25=0,"",F25/(F25+G25))
C26: Requisito del control | E26: =COUNTIF('Pauta Auditoría'!$D$10:$D$113,C26) -> 23 | F26: =COUNTIFS('Pauta Auditoría'!$D$10:$D$113,C26,'Pauta Auditoría'!$I$10:$I$113,"C") -> 0 | G26: =COUNTIFS('Pauta Auditoría'!$D$10:$D$113,C26,'Pauta Auditoría'!$I$10:$I$113,"NC") -> 0 | H26: =COUNTIFS('Pauta Auditoría'!$D$10:$D$113,C26,'Pauta Auditoría'!$I$10:$I$113,"NA") -> 0 | I26: =IF(F26+G26=0,"",F26/(F26+G26))
B28: C. RESULTADO DE LA AUDITORÍA
B29: % CUMPLIMIENTO GLOBAL | E29: =I19
B30: CALIFICACIÓN | E30: =IF(F19+G19=0,"SIN EVALUAR",IF(J19>0,"NO CONFORME – DESVIACIÓN CRÍTICA: DETENER Y REPORTAR",IF(I19>=0.9,"SATISFACTORIO",IF(I19>=0.75,"ACEPTABLE CON OBSERVACIONES","DEFICIENTE")))) -> SIN EVALUAR
B31: Criterio: ≥ 90 % Satisfactorio · 75 % – 89 % Aceptable con observaciones · < 75 % Deficiente · cualquier desviación crítica observada = NO CONFORME. (Umbrales propuestos, ajustables.)
B33: CONCLUSIONES DEL AUDITOR/A:
B34: AUDITOR/A LÍDER (NOMBRE, CARGO Y FIRMA): | E34: DUEÑO/A DEL CONTROL (NOMBRE, CARGO Y FIRMA):
B35: REVISA (NOMBRE, CARGO Y FIRMA): | E35: FECHA DE CIERRE DE ACCIONES:
